Workbook

Sheet Account 
A1: BNK - Humor
A2: No | B2: Contract | C2: Date | D2: Details | E2: M-Tone | F2: Unit Price | G2: T-Credit | H2: T-Debit | I2: Balance | K2: Rate | L2: T-Credit | M2: T-Debit | N2: Balance
A3: 1
A4: 2
A5: 3
A6: 4
A7: 5
A8: 6
A9: 7
A10: 8
A11: 9
A12: 10
A13: 11
A14: 12
... A120: 118
A121: 119 | P121: شروع
A122: 120
A123: 121
A124: 122
A125: 123
A126: 124 | I126: =G126-H126+I125 -> 0 | N126: =L126-M126+N125 -> 0
A127: 125 | B127: M - 32 | D127: Recived 199 Wagons # Avarage december -121.31 # | E127: =12006.4+2139.35 -> 14145.75 | F127: 41596.75 | H127: =E127*F127 -> 5.8841723e+08 | I127: =G127-H127+I126 -> -5.8841723e+08 | K127: =651.88-121.31 -> 530.57 | M127: =E127*K127 -> 7505310.6 | N127: =L127-M127+N126 -> -7505310.6 | P127: 86 | Q127: 651.88095 | R127: =Q127-35 -> 616.88095
A128: 126 | C128: 17/12/2025 | D128: Paid recipt no 648 by Sarafi Noorzad | G128: 500000000 | I128: =G128-H128+I127 -> -88417226 | K128: 78.400117 | L128: =G128/K128 -> 6377541.5 | N128: =L128-M128+N127 -> -1127769.1
A129: 127 | C129: 23/12/2025 | D129: Paid recipt no 666 by Sarafi Noorzad # 200 M | G129: 1.0185766e+08 | I129: =G129-H129+I128 -> 13440437 | K129: 78.400117 | L129: =G129/K129 -> 1299203 | N129: =L129-M129+N128 -> 171433.89
A130: 128 | C130: 24/12/2025 | D130: From contract M - 30 | G130: 1.9454619e+08 | I130: =G130-H130+I129 -> 2.0798662e+08 | K130: 78.400117 | L130: =G130/K130 -> 2481452.8 | N130: =L130-M130+N129 -> 2652886.7
A131: 129 | C131: 46174 | D131: From contract M - 29 | G131: 4210124.4 | I131: =G131-H131+I130 -> 2.1219675e+08 | K131: 78.400117 | L131: =G131/K131 -> 53700.486 | N131: =L131-M131+N130 -> 2706587.1
A132: 130 | C132: 46174 | D132: From contract M - 33 | H132: 2752469.5 | I132: =G132-H132+I131 -> 2.0944428e+08 | K132: 78.400117 | M132: =H132/K132 -> 35107.977 | N132: =L132-M132+N131 -> 2671479.2
A133: 131 | C133: 28.01.2026 | D133: Recived to contract 35-М | H133: 1.1411863e+08 | I133: =G133-H133+I132 -> 95325645 | K133: 78.400117 | M133: =H133/K133 -> 1455592.7 | N133: =L133-M133+N132 -> 1215886.5
A134: 132 | C134: 09.02.2026 | D134: Recived to Rent of wagons Account | H134: 32500168 | I134: =G134-H134+I133 -> 62825476 | K134: 78.400117 | M134: =H134/K134 -> 414542.34 | N134: =L134-M134+N133 -> 801344.17
A135: 133 | C135: 06.03.2026 | D135: Recived to Solvex - March loading | H135: 39264820 | I135: =G135-H135+I134 -> 23560656 | K135: 78.400117 | M135: =H135/K135 -> 500826.04 | N135: =L135-M135+N134 -> 300518.12
A136: 134 | C136: 24.03.2026 | D136: Recived to contract M - 37 | H136: 23560656 | I136: =G136-H136+I135 -> 0.017500006 | K136: 78.400117 | M136: =H136/K136 -> 300518.12 | N136: =L136-M136+N135 -> 0.00022321538
A137: 135 | I137: =G137-H137+I136 -> 0.017500006 | N137: =L137-M137+N136 -> 0.00022321538
A138: 136 | B138: M - 33 | C138: 46174 | D138: From contract M - 29 | G138: 2676324.9 | I138: =G138-H138+I137 -> 2676325 | K138: 78.4 | L138: =G138/K138 -> 34136.798 | N138: =L138-M138+N137 -> 34136.798
A139: 137 | C139: 46174 | D139: From contract M - 30 | G139: 22785445 | I139: =G139-H139+I138 -> 25461770 | K139: 78.4 | L139: =G139/K139 -> 290630.68 | N139: =L139-M139+N138 -> 324767.47
A140: 138 | C140: 46174 | D140: From contract M - 30 | G140: 6890484 | I140: =G140-H140+I139 -> 32352254 | K140: 78.4 | L140: =G140/K140 -> 87888.827 | N140: =L140-M140+N139 -> 412656.3
A141: 139 | C141: 46174 | D141: From contract M - 30 | G141: 6238180.8 | I141: =G141-H141+I140 -> 38590435 | K141: 78.4 | L141: =G141/K141 -> 79568.633 | N141: =L141-M141+N140 -> 492224.93
A142: 140 | C142: 46174 | D142: From contract M - 32 | G142: 2752469.5 | I142: =G142-H142+I141 -> 41342904 | K142: 78.4 | L142: =G142/K142 -> 35108.029 | N142: =L142-M142+N141 -> 527332.96
A143: 141 | D143: Recived 14 Wagons # Avarage of December -122.43 # | E143: 824.171 | F143: 41508.94 | H143: =E143*F143 -> 34210465 | I143: =G143-H143+I142 -> 7132439.7 | K143: 529.45 | M143: =E143*K143 -> 436357.34 | N143: =L143-M143+N142 -> 90975.627
A144: 142 | D144: Recived to Solvex - March loading | H144: 241955.61 | I144: =G144-H144+I143 -> 6890484.1 | K144: 78.4 | M144: =H144/K144 -> 3086.1685 | N144: =L144-M144+N143 -> 87889.458
A145: 143 | D145: Recived to contract M - 37 | H145: 6890484 | I145: =G145-H145+I144 -> 0.018759994 | K145: 78.4 | M145: 87889.458 | N145: =L145-M145+N144 -> 0.00022321544
...

Sheet Rent 
A1: BNK # Rent of Wagons
A2: No | B2: Date | C2: Details | D2: M-Tone | E2: Unit Price | F2: T-Credit | G2: T-Debit | H2: Balance | J2: Rate | K2: T-Credit | L2: T-Debit | M2: Balance
A25: 23 | C25: Rent of wagons # contract M - 32 | D25: 14145.75 | E25: 6537.9 | G25: =D25*E25 -> 92483499 | H25: =F25-G25+H24 -> -92483499 | J25: 78.3941 | L25: =D25*J25 -> 1108943.3 | M25: =K25-L25+M24 -> -1108943.3
A26: 24 | C26: Rent of wagons # contract M - 33 | D26: 824.171 | E26: 6626.86 | G26: =D26*E26 -> 5461665.8 | H26: =F26-G26+H25 -> -97945165 | J26: 78.3941 | L26: =D26*J26 -> 64610.144 | M26: =K26-L26+M25 -> -1173553.5
A27: 25 | B27: 13/1/2026 | C27: Paid recipt no 2 by Sarafi Noorzad # 400 M | F27: 98061150 | H27: =F27-G27+H26 -> 115985.24 | J27: 77.215566 | K27: =F27/J27 -> 1269966.1 | M27: =K27-L27+M26 -> 96412.607
A28: 26 | B28: 16/1/2026 | C28: Paid recipt no 14 by Monib Omar # 300 M | F28: 38570719 | H28: =F28-G28+H27 -> 38686704 | J28: 77.447767 | K28: =F28/J28 -> 498022.35 | M28: =K28-L28+M27 -> 594434.96
A29: 27 | B29: 23/1/2026 | C29: Paid recipt no 93 by Sarafi Noorzad # 100 M | F29: 11120134 | H29: =F29-G29+H28 -> 49806839 | J29: 77.447767 | K29: =F29/J29 -> 143582.38 | M29: =K29-L29+M28 -> 738017.33
A30: 28 | C30: Contract 15000 MT Gasoline # M - 34 | D30: 14983.95 | E30: 6537.41 | G30: =D30*E30 -> 97956225 | H30: =F30-G30+H29 -> -48149386 | J30: 80 | L30: =D30*J30 -> 1198716 | M30: =K30-L30+M29 -> -460698.67
A31: 29 | B31: 09.02.2026 | C31: Акт взаимозачет №3-М/8-4-13/66 из ДС-32М | F31: 32500168 | H31: =F31-G31+H30 -> -15649218 | J31: 78.400117 | K31: =F31/J31 -> 414542.34 | M31: =K31-L31+M30 -> -46156.321
A32: 30 | B32: 02.02.2026 | C32: Paid recipt no 139 by Noorzad Dubai 150 M | F32: 15870128 | H32: =F32-G32+H31 -> 220910.67 | J32: 77.447767 | K32: =F32/J32 -> 204913.96 | M32: =K32-L32+M31 -> 158757.64
A33: 31 | C33: Contract 15000 MT Diesel # M - 35 | D33: 11117.65 | E33: 6537.41 | G33: =D33*E33 -> 72680636 | H33: =F33-G33+H32 -> -72459726 | J33: 82.5 | L33: =D33*J33 -> 917206.12 | M33: =K33-L33+M32 -> -758448.49
A34: 32 | C34: From contract M - 37 | F34: 96000000 | H34: =F34-G34+H33 -> 23540274 | J34: 76.967271 | K34: =F34/J34 -> 1247283.4 | M34: =K34-L34+M33 -> 488834.92
A35: 33 | C35: Contract 15000 MT Gasoline # M - 37 | D35: 14966.95 | E35: 6383.391 | G35: =D35*E35 -> 95539894 | H35: =F35-G35+H34 -> -71999620 | J35: 85 | L35: =D35*J35 -> 1272190.7 | M35: =K35-L35+M34 -> -783355.83
A36: 34 | C36: From contract M - 38 | F36: 50000000 | H36: =F36-G36+H35 -> -21999620 | J36: 76.889615 | K36: =F36/J36 -> 650282.88 | M36: =K36-L36+M35 -> -133072.95
A37: 35 | C37: Contract 10000 MT Gasoline # M - 38 | D37: 9982.7 | E37: 6714.786 | G37: =D37*E37 -> 67031694 | H37: =F37-G37+H36 -> -89031314 | J37: 84 | L37: =D37*J37 -> 838546.8 | M37: =K37-L37+M36 -> -971619.75
A38: 36 | H38: =F38-G38+H37 -> -89031314 | M38: =K38-L38+M37 -> -971619.75 | P38: =H38/M38 -> 91.631848
A39: 37 | H39: =F39-G39+H38 -> -89031314 | M39: =K39-L39+M38 -> -971619.75
A40: 38 | H40: =F40-G40+H39 -> -89031314 | M40: =K40-L40+M39 -> -971619.75
A41: 39 | H41: =F41-G41+H40 -> -89031314 | M41: =K41-L41+M40 -> -971619.75

Sheet 14170 MT
A1: Contract BNK-KHM/9-4-12/140 dd 29.07.2022, between "BNK-FZCO" (UAE) and "KHUMOR" LLC (KYRGYZ REPUBLIC) | T1: AI-92-K5
A2: ADDENDUM № 32-M dd 17.12.25 (FCA BARBAROV) 14'170 mt
F3: -121,31$
A4: № | B4: Date | C4: RWB No | D4: Wagons No | E4: Loaded quantity (MT) | F4: Price in December 01.12.25-31.12.25 $ | G4: Total | H4: Fix price in rub | I4: Total | J4: Consignee | K4: Destination | M4: transport included in the product price | Q4: Date of arrival of wagons | R4: Date of leak | S4: Quantity | T4: Difference | U4: Remarks
A5: 1 | B5: 46019 | C5: 9109855 | D5: 50035534 | E5: 60.85 | F5: =[1]Platts2025!AD34-121.31 -> 530.57095 | G5: =E5*F5 -> 32285.242 | H5: 48581.26 | I5: =E5*H5 -> 2956169.7 | J5: Terminal Ilinka | K5: Barbarov | R5: 46026 | S5: 61.011 | T5: =S5-E5 -> 0.161
A6: =A5+1 -> 2 | B6: 46019 | C6: 9109855 | D6: 50393693 | E6: 61.05 | F6: 530.57 | G6: =E6*F6 -> 32391.299 | H6: 48581.26 | I6: =E6*H6 -> 2965885.9 | J6: Terminal Ilinka | K6: Barbarov | R6: 46026 | S6: 60.818 | T6: =S6-E6 -> -0.232
A7: =A6+1 -> 3 | B7: 46019 | C7: 9109858 | D7: 50424894 | E7: 61.4 | F7: 530.57 | G7: =E7*F7 -> 32576.998 | H7: 48581.26 | I7: =E7*H7 -> 2982889.4 | J7: Terminal Ilinka | K7: Barbarov | R7: 46026 | S7: 61.705 | T7: =S7-E7 -> 0.305
A8: =A7+1 -> 4 | B8: 46019 | C8: 9109855 | D8: 50428069 | E8: 61.05 | F8: 530.57 | G8: =E8*F8 -> 32391.299 | H8: 48581.26 | I8: =E8*H8 -> 2965885.9 | J8: Terminal Ilinka | K8: Barbarov | R8: 46026 | S8: 61.12 | T8: =S8-E8 -> 0.07
A9: =A8+1 -> 5 | B9: 46019 | C9: 9109859 | D9: 50464981 | E9: 53 | F9: 530.57 | G9: =E9*F9 -> 28120.21 | H9: 48581.26 | I9: =E9*H9 -> 2574806.8 | J9: Terminal Ilinka | K9: Barbarov
A10: =A9+1 -> 6 | B10: 46019 | C10: 9109857 | D10: 50480961 | E10: 61 | F10: 530.57 | G10: =E10*F10 -> 32364.77 | H10: 48581.26 | I10: =E10*H10 -> 2963456.9 | J10: Terminal Ilinka | K10: Barbarov | R10: 46026 | S10: 61.539 | T10: =S10-E10 -> 0.539
A11: =A10+1 -> 7 | B11: 46019 | C11: 9109855 | D11: 50497171 | E11: 61 | F11: 530.57 | G11: =E11*F11 -> 32364.77 | H11: 48581.26 | I11: =E11*H11 -> 2963456.9 | J11: Terminal Ilinka | K11: Barbarov | R11: 46026 | S11: 61.098 | T11: =S11-E11 -> 0.098
A12: =A11+1 -> 8 | B12: 46019 | C12: 9109858 | D12: 50723840 | E12: 60.85 | F12: 530.57 | G12: =E12*F12 -> 32285.185 | H12: 48581.26 | I12: =E12*H12 -> 2956169.7 | J12: Terminal Ilinka | K12: Barbarov
A13: =A12+1 -> 9 | B13: 46019 | C13: 9109858 | D13: 50723907 | E13: 60.8 | F13: 530.57 | G13: =E13*F13 -> 32258.656 | H13: 48581.26 | I13: =E13*H13 -> 2953740.6 | J13: Terminal Ilinka | K13: Barbarov
A14: =A13+1 -> 10 | B14: 46019 | C14: 9109858 | D14: 50751890 | E14: 61.3 | F14: 530.57 | G14: =E14*F14 -> 32523.941 | H14: 48581.26 | I14: =E14*H14 -> 2978031.2 | J14: Terminal Ilinka | K14: Barbarov | R14: 46026 | S14: 61.467 | T14: =S14-E14 -> 0.167
A15: =A14+1 -> 11 | B15: 46019 | C15: 9109855 | D15: 51378982 | E15: 51.95 | F15: 530.57 | G15: =E15*F15 -> 27563.112 | H15: 48581.26 | I15: =E15*H15 -> 2523796.5 | J15: Terminal Ilinka | K15: Barbarov | R15: 46029 | S15: 51.753 | T15: =S15-E15 -> -0.197
A16: =A15+1 -> 12 | B16: 46019 | C16: 9109858 | D16: 51411882 | E16: 60.65 | F16: 530.57 | G16: =E16*F16 -> 32179.071 | H16: 48581.26 | I16: =E16*H16 -> 2946453.4 | J16: Terminal Ilinka | K16: Barbarov
A17: =A16+1 -> 13 | B17: 46019 | C17: 9109855 | D17: 51435709 | E17: 52.55 | F17: 530.57 | G17: =E17*F17 -> 27881.453 | H17: 48581.26 | I17: =E17*H17 -> 2552945.2 | J17: Terminal Ilinka | K17: Barbarov | R17: 46026 | S17: 52.638 | T17: =S17-E17 -> 0.088
A18: =A17+1 -> 14 | B18: 46019 | C18: 9109858 | D18: 51458354 | E18: 60.55 | F18: 530.57 | G18: =E18*F18 -> 32126.014 | H18: 48581.26 | I18: =E18*H18 -> 2941595.3 | J18: Terminal Ilinka | K18: Barbarov | R18: 46026 | S18: 61.061 | T18: =S18-E18 -> 0.511
A19: =A18+1 -> 15 | B19: 46019 | C19: 9109858 | D19: 51664332 | E19: 52.25 | F19: 530.57 | G19: =E19*F19 -> 27722.283 | H19: 48581.26 | I19: =E19*H19 -> 2538370.8 | J19: Terminal Ilinka | K19: Barbarov
A20: =A19+1 -> 16 | B20: 46019 | C20: 9109858 | D20: 51722726 | E20: 51.85 | F20: 530.57 | G20: =E20*F20 -> 27510.055 | H20: 48581.26 | I20: =E20*H20 -> 2518938.3 | J20: Terminal Ilinka | K20: Barbarov | R20: 46026 | S20: 51.808 | T20: =S20-E20 -> -0.042
A21: =A20+1 -> 17 | B21: 46019 | C21: 9109859 | D21: 51887388 | E21: 61.35 | F21: 530.57 | G21: =E21*F21 -> 32550.47 | H21: 48581.26 | I21: =E21*H21 -> 2980460.3 | J21: Terminal Ilinka | K21: Barbarov
A22: =A21+1 -> 18 | B22: 46019 | C22: 9109859 | D22: 53888053 | E22: 60.85 | F22: 530.57 | G22: =E22*F22 -> 32285.185 | H22: 48581.26 | I22: =E22*H22 -> 2956169.7 | J22: Terminal Ilinka | K22: Barbarov
A23: =A22+1 -> 19 | B23: 46019 | C23: 9109859 | D23: 53974952 | E23: 51.5 | F23: 530.57 | G23: =E23*F23 -> 27324.355 | H23: 48581.26 | I23: =E23*H23 -> 2501934.9 | J23: Terminal Ilinka | K23: Barbarov
A24: =A23+1 -> 20 | B24: 46019 | C24: 9109859 | D24: 53985446 | E24: 52.5 | F24: 530.57 | G24: =E24*F24 -> 27854.925 | H24: 48581.26 | I24: =E24*H24 -> 2550516.1 | J24: Terminal Ilinka | K24: Barbarov
A25: =A24+1 -> 21 | B25: 46019 | C25: 9109855 | D25: 54070867 | E25: 60.8 | F25: 530.57 | G25: =E25*F25 -> 32258.656 | H25: 48581.26 | I25: =E25*H25 -> 2953740.6 | J25: Terminal Ilinka | K25: Barbarov | R25: 46026 | S25: 60.916 | T25: =S25-E25 -> 0.116
A26: =A25+1 -> 22 | B26: 46019 | C26: 9109858 | D26: 54240213 | E26: 61.35 | F26: 530.57 | G26: =E26*F26 -> 32550.47 | H26: 48581.26 | I26: =E26*H26 -> 2980460.3 | J26: Terminal Ilinka | K26: Barbarov
A27: =A26+1 -> 23 | B27: 46019 | C27: 9109858 | D27: 54253109 | E27: 61.25 | F27: 530.57 | G27: =E27*F27 -> 32497.413 | H27: 48581.26 | I27: =E27*H27 -> 2975602.2 | J27: Terminal Ilinka | K27: Barbarov | R27: 46026 | S27: 61.539 | T27: =S27-E27 -> 0.289
A28: =A27+1 -> 24 | B28: 46019 | C28: 9109859 | D28: 55945927 | E28: 61.3 | F28: 530.57 | G28: =E28*F28 -> 32523.941 | H28: 48581.26 | I28: =E28*H28 -> 2978031.2 | J28: Terminal Ilinka | K28: Barbarov
A29: =A28+1 -> 25 | B29: 46019 | C29: 9109859 | D29: 57227969 | E29: 61.25 | F29: 530.57 | G29: =E29*F29 -> 32497.413 | H29: 48581.26 | I29: =E29*H29 -> 2975602.2 | J29: Terminal Ilinka | K29: Barbarov
A30: =A29+1 -> 26 | B30: 46019 | C30: 9109859 | D30: 57353153 | E30: 52.85 | F30: 530.57 | G30: =E30*F30 -> 28040.625 | H30: 48581.26 | I30: =E30*H30 -> 2567519.6 | J30: Terminal Ilinka | K30: Barbarov
A31: =A30+1 -> 27 | B31: 46019 | C31: 9109855 | D31: 57417883 | E31: 60.85 | F31: 530.57 | G31: =E31*F31 -> 32285.185 | H31: 48581.26 | I31: =E31*H31 -> 2956169.7 | J31: Terminal Ilinka | K31: Barbarov | R31: 46026 | S31: 60.783 | T31: =S31-E31 -> -0.067
A32: =A31+1 -> 28 | B32: 46019 | C32: 9109859 | D32: 57424491 | E32: 60.75 | F32: 530.57 | G32: =E32*F32 -> 32232.128 | H32: 48581.26 | I32: =E32*H32 -> 2951311.5 | J32: Terminal Ilinka | K32: Barbarov
A33: =A32+1 -> 29 | B33: 46019 | C33: 9109857 | D33: 58345307 | E33: 60.85 | F33: 530.57 | G33: =E33*F33 -> 32285.185 | H33: 48581.26 | I33: =E33*H33 -> 2956169.7 | J33: Terminal Ilinka | K33: Barbarov | R33: 46026 | S33: 60.567 | T33: =S33-E33 -> -0.283
A34: =A33+1 -> 30 | B34: 46019 | C34: 9109855 | D34: 73019945 | E34: 61.35 | F34: 530.57 | G34: =E34*F34 -> 32550.47 | H34: 48581.26 | I34: =E34*H34 -> 2980460.3 | J34: Terminal Ilinka | K34: Barbarov | R34: 46026 | S34: 59.937 | T34: =S34-E34 -> -1.413
A35: =A34+1 -> 31 | B35: 46019 | C35: 9109855 | D35: 73022477 | E35: 61.4 | F35: 530.57 | G35: =E35*F35 -> 32576.998 | H35: 48581.26 | I35: =E35*H35 -> 2982889.4 | J35: Terminal Ilinka | K35: Barbarov | R35: 46029 | S35: 61.149 | T35: =S35-E35 -> -0.251
A36: =A35+1 -> 32 | B36: 46019 | C36: 9109857 | D36: 73072340 | E36: 61.35 | F36: 530.57 | G36: =E36*F36 -> 32550.47 | H36: 48581.26 | I36: =E36*H36 -> 2980460.3 | J36: Terminal Ilinka | K36: Barbarov | R36: 46026 | S36: 61.212 | T36: =S36-E36 -> -0.138
A37: =A36+1 -> 33 | B37: 46019 | C37: 9109857 | D37: 73081275 | E37: 61.55 | F37: 530.57 | G37: =E37*F37 -> 32656.584 | H37: 48581.26 | I37: =E37*H37 -> 2990176.6 | J37: Terminal Ilinka | K37: Barbarov | R37: 46026 | S37: 61.403 | T37: =S37-E37 -> -0.147
A38: =A37+1 -> 34 | B38: 46019 | C38: 9109858 | D38: 73098600 | E38: 61.35 | F38: 530.57 | G38: =E38*F38 -> 32550.47 | H38: 48581.26 | I38: =E38*H38 -> 2980460.3 | J38: Terminal Ilinka | K38: Barbarov
A39: =A38+1 -> 35 | B39: 46019 | C39: 9109857 | D39: 73109662 | E39: 61.45 | F39: 530.57 | G39: =E39*F39 -> 32603.527 | H39: 48581.26 | I39: =E39*H39 -> 2985318.4 | J39: Terminal Ilinka | K39: Barbarov | R39: 46026 | S39: 61.351 | T39: =S39-E39 -> -0.099
A40: =A39+1 -> 36 | B40: 46019 | C40: 9109855 | D40: 73117988 | E40: 61.3 | F40: 530.57 | G40: =E40*F40 -> 32523.941 | H40: 48581.26 | I40: =E40*H40 -> 2978031.2 | J40: Terminal Ilinka | K40: Barbarov | R40: 46029 | S40: 61.428 | T40: =S40-E40 -> 0.128
...

Sheet 830 MT
A1: Contract BNK-KHM/9-4-12/140 dd 29.07.2022, between "BNK-FZCO" (UAE) and "KHUMOR" LLC (KYRGYZ REPUBLIC) | T1: AI-92-K5
A2: ADDENDUM № 33-M dd 17.12.25 (FCA NOVOPOLOTSK) 830 mt
F3: -122,43$
A4: № | B4: Date | C4: RWB No | D4: Wagons No | E4: Loaded quantity (MT) | F4: Price in December 01.12.25-31.12.25 $ | G4: Total | H4: Fix price in rub | I4: Total | J4: Consignee | K4: Destination | M4: transport included in the product price | Q4: Date of arrival of wagons | R4: Date of leak | S4: Quantity | T4: Difference | U4: Remarks
A5: 1 | B5: 46031 | C5: 9983074 | D5: 50197284 | E5: 56.243 | F5: =[1]Platts2025!AH34-122.43 -> 512.33471 | G5: =E5*F5 -> 28815.241 | H5: 41508.94 | I5: =E5*H5 -> 2334587.3 | J5: Terminal Ilinka | K5: Novopolotsk | R5: 46040 | S5: 56.647 | T5: =S5-E5 -> 0.404
A6: =A5+1 -> 2 | B6: 46031 | C6: 9983074 | D6: 51147684 | E6: 57.546 | F6: 488.82 | G6: =E6*F6 -> 28129.636 | H6: 41508.94 | I6: =E6*H6 -> 2388673.5 | J6: Terminal Ilinka | K6: Novopolotsk | R6: 46040 | S6: 57.754 | T6: =S6-E6 -> 0.208
A7: =A6+1 -> 3 | B7: 46031 | C7: 9983074 | D7: 51867471 | E7: 57.445 | F7: 488.82 | G7: =E7*F7 -> 28080.265 | H7: 41508.94 | I7: =E7*H7 -> 2384481.1 | J7: Terminal Ilinka | K7: Novopolotsk | R7: 46040 | S7: 57.59 | T7: =S7-E7 -> 0.145
A8: =A7+1 -> 4 | B8: 46031 | C8: 9983074 | D8: 57190753 | E8: 58.948 | F8: 488.82 | G8: =E8*F8 -> 28814.961 | H8: 41508.94 | I8: =E8*H8 -> 2446869 | J8: Terminal Ilinka | K8: Novopolotsk | R8: 46040 | S8: 58.135 | T8: =S8-E8 -> -0.813
A9: =A8+1 -> 5 | B9: 46031 | C9: 9983074 | D9: 73901266 | E9: 57.345 | F9: 488.82 | G9: =E9*F9 -> 28031.383 | H9: 41508.94 | I9: =E9*H9 -> 2380330.2 | J9: Terminal Ilinka | K9: Novopolotsk | R9: 46040 | S9: 56.932 | T9: =S9-E9 -> -0.413
A10: =A9+1 -> 6 | B10: 46031 | C10: 9983074 | D10: 75004127 | E10: 58.297 | F10: 488.82 | G10: =E10*F10 -> 28496.74 | H10: 41508.94 | I10: =E10*H10 -> 2419846.7 | J10: Terminal Ilinka | K10: Novopolotsk | R10: 46040 | S10: 57.902 | T10: =S10-E10 -> -0.395
A11: =A10+1 -> 7 | B11: 46031 | C11: 9983074 | D11: 75671792 | E11: 60.601 | F11: 488.82 | G11: =E11*F11 -> 29622.981 | H11: 41508.94 | I11: =E11*H11 -> 2515483.3 | J11: Terminal Ilinka | K11: Novopolotsk | R11: 46040 | S11: 60.649 | T11: =S11-E11 -> 0.048
A12: =A11+1 -> 8 | B12: 46031 | C12: 9983074 | D12: 75671990 | E12: 60 | F12: 488.82 | G12: =E12*F12 -> 29329.2 | H12: 41508.94 | I12: =E12*H12 -> 2490536.4 | J12: Terminal Ilinka | K12: Novopolotsk | R12: 46040 | S12: 60.174 | T12: =S12-E12 -> 0.174
A13: =A12+1 -> 9 | B13: 46031 | C13: 9983074 | D13: 75672097 | E13: 60.601 | F13: 488.82 | G13: =E13*F13 -> 29622.981 | H13: 41508.94 | I13: =E13*H13 -> 2515483.3 | J13: Terminal Ilinka | K13: Novopolotsk | R13: 46040 | S13: 60.748 | T13: =S13-E13 -> 0.147
A14: =A13+1 -> 10 | B14: 46031 | C14: 9983074 | D14: 75673293 | E14: 60.15 | F14: 488.82 | G14: =E14*F14 -> 29402.523 | H14: 41508.94 | I14: =E14*H14 -> 2496762.7 | J14: Terminal Ilinka | K14: Novopolotsk | R14: 46040 | S14: 59.794 | T14: =S14-E14 -> -0.356
A15: =A14+1 -> 11 | B15: 46031 | C15: 9983074 | D15: 75673491 | E15: 60.551 | F15: 488.82 | G15: =E15*F15 -> 29598.54 | H15: 41508.94 | I15: =E15*H15 -> 2513407.8 | J15: Terminal Ilinka | K15: Novopolotsk | R15: 46040 | S15: 60.597 | T15: =S15-E15 -> 0.046
A16: =A15+1 -> 12 | B16: 46031 | C16: 9983074 | D16: 75673590 | E16: 60.05 | F16: 488.82 | G16: =E16*F16 -> 29353.641 | H16: 41508.94 | I16: =E16*H16 -> 2492611.8 | J16: Terminal Ilinka | K16: Novopolotsk | R16: 46040 | S16: 60.261 | T16: =S16-E16 -> 0.211
A17: =A16+1 -> 13 | B17: 46031 | C17: 9983074 | D17: 75674390 | E17: 58.147 | F17: 488.82 | G17: =E17*F17 -> 28423.417 | H17: 41508.94 | I17: =E17*H17 -> 2413620.3 | J17: Terminal Ilinka | K17: Novopolotsk
A18: =A17+1 -> 14 | B18: 46031 | C18: 9983074 | D18: 75675298 | E18: 58.247 | F18: 488.82 | G18: =E18*F18 -> 28472.299 | H18: 41508.94 | I18: =E18*H18 -> 2417771.2 | J18: Terminal Ilinka | K18: Novopolotsk
E19: =SUM(E5:E18) -> 824.171 | G19: =SUM(G5:G18) -> 404193.81 | I19: =SUM(I5:I18) -> 34210465 | S19: =SUM(S5:S18) -> 707.183 | T19: =SUM(T5:T18) -> -0.594
E20: =E19 -> 824.171 | G20: =G19 -> 404193.81 | I20: =I19 -> 34210465 | S20: =S19 -> 707.183 | T20: =T19 -> -0.594
B22: FULL TONNAGE | E22: 830
B23: LOADED | E23: =E20 -> 824.171
B24: BALANCE | E24: =E22-E23 -> 5.829 | G24: 78.3941

Sheet  34-M AI-92 -15000 MT 
A1: Contract BNK-KHM/9-4-12/140 dd 29.07.2022, between "BNK-FZCO" (UAE) and "KHUMOR" LLC (KYRGYZ REPUBLIC) | T1: AI-92-K5
A2: ADDENDUM № 34-M dd 06.01.26 (FCA BARBAROV) 15'000 mt
F3: -121,57$ | W3: 46076.86
A4: № | B4: Date | C4: RWB No | D4: Wagons No | E4: Loaded quantity (MT) | F4: Price in January 01.01.26-31.01.26 $ | G4: Total | H4: Fix price in rub | I4: Total | J4: Consignee | K4: Destination | M4: transport included in the product price | Q4: Date of arrival of wagons | R4: Date of leak | S4: Quantity | T4: Difference | U4: Remarks
A5: 1 | B5: 46045 | C5: 8610245 | D5: 50220904 | E5: 61 | F5: ='[2]Platt''s 2026'!B34-121.57 -> 520.11182 | G5: =E5*F5 -> 31726.821 | H5: 46076.86 | I5: =E5*H5 -> 2810688.5 | J5: Terminal Ilinka | K5: Barbarov
A6: =A5+1 -> 2 | B6: 46045 | C6: 8610246 | D6: 50413400 | E6: 60.95 | F6: 520.11 | G6: =E6*F6 -> 31700.705 | H6: 46076.86 | I6: =E6*H6 -> 2808384.6 | J6: Terminal Ilinka | K6: Barbarov | R6: 46054 | S6: 60.852 | T6: =S6-E6 -> -0.098
A7: =A6+1 -> 3 | B7: 46045 | C7: 8610246 | D7: 51833374 | E7: 61.1 | F7: 520.11 | G7: =E7*F7 -> 31778.721 | H7: 46076.86 | I7: =E7*H7 -> 2815296.1 | J7: Terminal Ilinka | K7: Barbarov | R7: 46054 | S7: 60.874 | T7: =S7-E7 -> -0.226
A8: =A7+1 -> 4 | B8: 46045 | C8: 8610245 | D8: 54026836 | E8: 60.95 | F8: 520.11 | G8: =E8*F8 -> 31700.705 | H8: 46076.86 | I8: =E8*H8 -> 2808384.6 | J8: Terminal Ilinka | K8: Barbarov
A9: =A8+1 -> 5 | B9: 46045 | C9: 8610245 | D9: 54721329 | E9: 61.2 | F9: 520.11 | G9: =E9*F9 -> 31830.732 | H9: 46076.86 | I9: =E9*H9 -> 2819903.8 | J9: Terminal Ilinka | K9: Barbarov
A10: =A9+1 -> 6 | B10: 46045 | C10: 8610246 | D10: 57429383 | E10: 60.9 | F10: 520.11 | G10: =E10*F10 -> 31674.699 | H10: 46076.86 | I10: =E10*H10 -> 2806080.8 | J10: Terminal Ilinka | K10: Barbarov | R10: 46054 | S10: 60.859 | T10: =S10-E10 -> -0.041
A11: =A10+1 -> 7 | B11: 46045 | C11: 8610245 | D11: 57434193 | E11: 60.95 | F11: 520.11 | G11: =E11*F11 -> 31700.705 | H11: 46076.86 | I11: =E11*H11 -> 2808384.6 | J11: Terminal Ilinka | K11: Barbarov
A12: =A11+1 -> 8 | B12: 46045 | C12: 8610245 | D12: 73021644 | E12: 61.5 | F12: 520.11 | G12: =E12*F12 -> 31986.765 | H12: 46076.86 | I12: =E12*H12 -> 2833726.9 | J12: Terminal Ilinka | K12: Barbarov
A13: =A12+1 -> 9 | B13: 46045 | C13: 8610245 | D13: 73049454 | E13: 61.5 | F13: 520.11 | G13: =E13*F13 -> 31986.765 | H13: 46076.86 | I13: =E13*H13 -> 2833726.9 | J13: Terminal Ilinka | K13: Barbarov
A14: =A13+1 -> 10 | B14: 46045 | C14: 8610245 | D14: 73062325 | E14: 61.55 | F14: 520.11 | G14: =E14*F14 -> 32012.77 | H14: 46076.86 | I14: =E14*H14 -> 2836030.7 | J14: Terminal Ilinka | K14: Barbarov
A15: =A14+1 -> 11 | B15: 46045 | C15: 8610246 | D15: 73069189 | E15: 61.7 | F15: 520.11 | G15: =E15*F15 -> 32090.787 | H15: 46076.86 | I15: =E15*H15 -> 2842942.3 | J15: Terminal Ilinka | K15: Barbarov | R15: 46054 | S15: 61.543 | T15: =S15-E15 -> -0.157
A16: =A15+1 -> 12 | B16: 46045 | C16: 8610246 | D16: 73071086 | E16: 61.5 | F16: 520.11 | G16: =E16*F16 -> 31986.765 | H16: 46076.86 | I16: =E16*H16 -> 2833726.9 | J16: Terminal Ilinka | K16: Barbarov | R16: 46054 | S16: 61.285 | T16: =S16-E16 -> -0.215
A17: =A16+1 -> 13 | B17: 46045 | C17: 8610245 | D17: 73084485 | E17: 61.7 | F17: 520.11 | G17: =E17*F17 -> 32090.787 | H17: 46076.86 | I17: =E17*H17 -> 2842942.3 | J17: Terminal Ilinka | K17: Barbarov
A18: =A17+1 -> 14 | B18: 46045 | C18: 8610245 | D18: 73090466 | E18: 61.55 | F18: 520.11 | G18: =E18*F18 -> 32012.77 | H18: 46076.86 | I18: =E18*H18 -> 2836030.7 | J18: Terminal Ilinka | K18: Barbarov
A19: =A18+1 -> 15 | B19: 46045 | C19: 8610245 | D19: 73115867 | E19: 61.75 | F19: 520.11 | G19: =E19*F19 -> 32116.792 | H19: 46076.86 | I19: =E19*H19 -> 2845246.1 | J19: Terminal Ilinka | K19: Barbarov
A20: =A19+1 -> 16 | B20: 46045 | C20: 8610245 | D20: 73173700 | E20: 61.55 | F20: 520.11 | G20: =E20*F20 -> 32012.77 | H20: 46076.86 | I20: =E20*H20 -> 2836030.7 | J20: Terminal Ilinka | K20: Barbarov
A21: =A20+1 -> 17 | B21: 46045 | C21: 8610246 | D21: 73183527 | E21: 61.55 | F21: 520.11 | G21: =E21*F21 -> 32012.77 | H21: 46076.86 | I21: =E21*H21 -> 2836030.7 | J21: Terminal Ilinka | K21: Barbarov | R21: 46054 | S21: 61.462 | T21: =S21-E21 -> -0.088
A22: =A21+1 -> 18 | B22: 46045 | C22: 8610246 | D22: 73187023 | E22: 61.55 | F22: 520.11 | G22: =E22*F22 -> 32012.77 | H22: 46076.86 | I22: =E22*H22 -> 2836030.7 | J22: Terminal Ilinka | K22: Barbarov | R22: 46054 | S22: 61.687 | T22: =S22-E22 -> 0.137
A23: =A22+1 -> 19 | B23: 46045 | C23: 8610246 | D23: 73205858 | E23: 61.35 | F23: 520.11 | G23: =E23*F23 -> 31908.749 | H23: 46076.86 | I23: =E23*H23 -> 2826815.4 | J23: Terminal Ilinka | K23: Barbarov | R23: 46054 | S23: 61.434 | T23: =S23-E23 -> 0.084
A24: =A23+1 -> 20 | B24: 46045 | C24: 8610245 | D24: 73220600 | E24: 61.5 | F24: 520.11 | G24: =E24*F24 -> 31986.765 | H24: 46076.86 | I24: =E24*H24 -> 2833726.9 | J24: Terminal Ilinka | K24: Barbarov
A25: =A24+1 -> 21 | B25: 46045 | C25: 8610245 | D25: 73230336 | E25: 61.7 | F25: 520.11 | G25: =E25*F25 -> 32090.787 | H25: 46076.86 | I25: =E25*H25 -> 2842942.3 | J25: Terminal Ilinka | K25: Barbarov
A26: =A25+1 -> 22 | B26: 46045 | C26: 8610245 | D26: 73230377 | E26: 61.45 | F26: 520.11 | G26: =E26*F26 -> 31960.76 | H26: 46076.86 | I26: =E26*H26 -> 2831423 | J26: Terminal Ilinka | K26: Barbarov
A27: =A26+1 -> 23 | B27: 46045 | C27: 8610245 | D27: 73230930 | E27: 61.5 | F27: 520.11 | G27: =E27*F27 -> 31986.765 | H27: 46076.86 | I27: =E27*H27 -> 2833726.9 | J27: Terminal Ilinka | K27: Barbarov
A28: =A27+1 -> 24 | B28: 46045 | C28: 8610246 | D28: 73231938 | E28: 61.35 | F28: 520.11 | G28: =E28*F28 -> 31908.749 | H28: 46076.86 | I28: =E28*H28 -> 2826815.4 | J28: Terminal Ilinka | K28: Barbarov | R28: 46054 | S28: 61.411 | T28: =S28-E28 -> 0.061
A29: =A28+1 -> 25 | B29: 46045 | C29: 8610246 | D29: 75229518 | E29: 61.65 | F29: 520.11 | G29: =E29*F29 -> 32064.782 | H29: 46076.86 | I29: =E29*H29 -> 2840638.4 | J29: Terminal Ilinka | K29: Barbarov | R29: 46054 | S29: 61.658 | T29: =S29-E29 -> 0.008
A30: =A29+1 -> 26 | B30: 46045 | C30: 8610246 | D30: 75256750 | E30: 61.6 | F30: 520.11 | G30: =E30*F30 -> 32038.776 | H30: 46076.86 | I30: =E30*H30 -> 2838334.6 | J30: Terminal Ilinka | K30: Barbarov | R30: 46054 | S30: 61.622 | T30: =S30-E30 -> 0.022
A31: =A30+1 -> 27 | B31: 46045 | C31: 8610246 | D31: 76322494 | E31: 61.65 | F31: 520.11 | G31: =E31*F31 -> 32064.782 | H31: 46076.86 | I31: =E31*H31 -> 2840638.4 | J31: Terminal Ilinka | K31: Barbarov | R31: 46054 | S31: 61.915 | T31: =S31-E31 -> 0.265
A32: =A31+1 -> 28 | B32: 46045 | C32: 8610245 | D32: 76351998 | E32: 61.75 | F32: 520.11 | G32: =E32*F32 -> 32116.792 | H32: 46076.86 | I32: =E32*H32 -> 2845246.1 | J32: Terminal Ilinka | K32: Barbarov
A33: =A32+1 -> 29 | B33: 46045 | C33: 8610245 | D33: 76352194 | E33: 62.1 | F33: 520.11 | G33: =E33*F33 -> 32298.831 | H33: 46076.86 | I33: =E33*H33 -> 2861373 | J33: Terminal Ilinka | K33: Barbarov
A34: =A33+1 -> 30 | B34: 46045 | C34: 8610246 | D34: 76427996 | E34: 61.85 | F34: 520.11 | G34: =E34*F34 -> 32168.804 | H34: 46076.86 | I34: =E34*H34 -> 2849853.8 | J34: Terminal Ilinka | K34: Barbarov | R34: 46054 | S34: 61.846 | T34: =S34-E34 -> -0.004
E35: =SUM(E5:E34) -> 1843.9 | G35: =SUM(G5:G34) -> 959030.94 | I35: =SUM(I5:I34) -> 84961122
A36: 31 | B36: 46046 | C36: 8610247 | D36: 58344888 | E36: 61.05 | F36: 520.11 | G36: =E36*F36 -> 31752.715 | H36: 46076.86 | I36: =E36*H36 -> 2812992.3 | J36: Terminal Ilinka | K36: Barbarov
A37: =A36+1 -> 32 | B37: 46046 | C37: 8610247 | D37: 73047516 | E37: 61.5 | F37: 520.11 | G37: =E37*F37 -> 31986.765 | H37: 46076.86 | I37: =E37*H37 -> 2833726.9 | J37: Terminal Ilinka | K37: Barbarov
A38: =A37+1 -> 33 | B38: 46046 | C38: 8610247 | D38: 73080210 | E38: 61.55 | F38: 520.11 | G38: =E38*F38 -> 32012.77 | H38: 46076.86 | I38: =E38*H38 -> 2836030.7 | J38: Terminal Ilinka | K38: Barbarov
A39: =A38+1 -> 34 | B39: 46046 | C39: 8610247 | D39: 73084477 | E39: 61.65 | F39: 520.11 | G39: =E39*F39 -> 32064.782 | H39: 46076.86 | I39: =E39*H39 -> 2840638.4 | J39: Terminal Ilinka | K39: Barbarov
A40: =A39+1 -> 35 | B40: 46046 | C40: 8610247 | D40: 73086019 | E40: 61.7 | F40: 520.11 | G40: =E40*F40 -> 32090.787 | H40: 46076.86 | I40: =E40*H40 -> 2842942.3 | J40: Terminal Ilinka | K40: Barbarov
...

Sheet 35 - M -15000 MT Diesel
A1: Contract BNK-KHM/9-4-12/140 dd 29.07.2022, between "BNK-FZCO" (UAE) and "KHUMOR" LLC (KYRGYZ REPUBLIC) | T1: Diesel DT-E-K5
A2: ADDENDUM № 35-M dd 12.01.26 (FCA BARBAROV) 15'000 mt
F3: -138,57$ | W3: 43524.16
A4: № | B4: Date | C4: RWB No | D4: Wagons No | E4: Loaded quantity (MT) | F4: Price in January 01.01.26-31.01.26 $ | G4: Total | H4: Fix price in rub | I4: Total | J4: Consignee | K4: Destination | M4: transport included in the product price | Q4: Date of arrival of wagons | R4: Date of leak | S4: Quantity | T4: Difference | U4: Remarks
A5: 1 | B5: 46050 | C5: 8610493 | D5: 54093679 | E5: 60.65 | F5: ='[3]Platt''s 2026'!F34-138.57 -> 495.79364 | G5: =E5*F5 -> 30069.884 | H5: 43524.16 | I5: =E5*H5 -> 2639740.3 | J5: Terminal Ilinka | K5: Barbarov
A6: =A5+1 -> 2 | B6: 46050 | C6: 8610492 | D6: 73006025 | E6: 61.25 | F6: 495.79 | G6: =E6*F6 -> 30367.138 | H6: 43524.16 | I6: =E6*H6 -> 2665854.8 | J6: Terminal Ilinka | K6: Barbarov
A7: =A6+1 -> 3 | B7: 46050 | C7: 8610493 | D7: 73009359 | E7: 60.6 | F7: 495.79 | G7: =E7*F7 -> 30044.874 | H7: 43524.16 | I7: =E7*H7 -> 2637564.1 | J7: Terminal Ilinka | K7: Barbarov
A8: =A7+1 -> 4 | B8: 46050 | C8: 8610492 | D8: 73045130 | E8: 59.75 | F8: 495.79 | G8: =E8*F8 -> 29623.452 | H8: 43524.16 | I8: =E8*H8 -> 2600568.6 | J8: Terminal Ilinka | K8: Barbarov
A9: =A8+1 -> 5 | B9: 46050 | C9: 8610492 | D9: 73107013 | E9: 63.6 | F9: 495.79 | G9: =E9*F9 -> 31532.244 | H9: 43524.16 | I9: =E9*H9 -> 2768136.6 | J9: Terminal Ilinka | K9: Barbarov
A10: =A9+1 -> 6 | B10: 46050 | C10: 8610493 | D10: 73118945 | E10: 61.6 | F10: 495.79 | G10: =E10*F10 -> 30540.664 | H10: 43524.16 | I10: =E10*H10 -> 2681088.3 | J10: Terminal Ilinka | K10: Barbarov
A11: =A10+1 -> 7 | B11: 46050 | C11: 8610492 | D11: 73126948 | E11: 60.65 | F11: 495.79 | G11: =E11*F11 -> 30069.663 | H11: 43524.16 | I11: =E11*H11 -> 2639740.3 | J11: Terminal Ilinka | K11: Barbarov
A12: =A11+1 -> 8 | B12: 46050 | C12: 8610492 | D12: 73131419 | E12: 61.15 | F12: 495.79 | G12: =E12*F12 -> 30317.558 | H12: 43524.16 | I12: =E12*H12 -> 2661502.4 | J12: Terminal Ilinka | K12: Barbarov
A13: =A12+1 -> 9 | B13: 46050 | C13: 8610492 | D13: 73158156 | E13: 61.05 | F13: 495.79 | G13: =E13*F13 -> 30267.98 | H13: 43524.16 | I13: =E13*H13 -> 2657150 | J13: Terminal Ilinka | K13: Barbarov
A14: =A13+1 -> 10 | B14: 46050 | C14: 8610492 | D14: 73161713 | E14: 60.55 | F14: 495.79 | G14: =E14*F14 -> 30020.085 | H14: 43524.16 | I14: =E14*H14 -> 2635387.9 | J14: Terminal Ilinka | K14: Barbarov
A15: =A14+1 -> 11 | B15: 46050 | C15: 8610492 | D15: 73182727 | E15: 61.15 | F15: 495.79 | G15: =E15*F15 -> 30317.558 | H15: 43524.16 | I15: =E15*H15 -> 2661502.4 | J15: Terminal Ilinka | K15: Barbarov
A16: =A15+1 -> 12 | B16: 46050 | C16: 8610493 | D16: 73230583 | E16: 60.1 | F16: 495.79 | G16: =E16*F16 -> 29796.979 | H16: 43524.16 | I16: =E16*H16 -> 2615802 | J16: Terminal Ilinka | K16: Barbarov
A17: =A16+1 -> 13 | B17: 46050 | C17: 8610492 | D17: 73230773 | E17: 59.15 | F17: 495.79 | G17: =E17*F17 -> 29325.979 | H17: 43524.16 | I17: =E17*H17 -> 2574454.1 | J17: Terminal Ilinka | K17: Barbarov
... A28: =A27+1 -> 24 | B28: 46050 | C28: 8610493 | D28: 76163393 | E28: 62.35 | F28: 495.79 | G28: =E28*F28 -> 30912.507 | H28: 43524.16 | I28: =E28*H28 -> 2713731.4 | J28: Terminal Ilinka | K28: Barbarov
E29: =SUM(E5:E28) -> 1464.9 | G29: =SUM(G5:G28) -> 726282.99 | I29: =SUM(I5:I28) -> 63758542
A30: 25 | B30: 46050 | C30: 8610498 | D30: 50416544 | E30: 57.5 | F30: 495.79 | G30: =E30*F30 -> 28507.925 | H30: 43524.16 | I30: =E30*H30 -> 2502639.2 | J30: Terminal Ilinka | K30: Barbarov
A31: =A30+1 -> 26 | B31: 46050 | C31: 8610498 | D31: 50485804 | E31: 57.35 | F31: 495.79 | G31: =E31*F31 -> 28433.557 | H31: 43524.16 | I31: =E31*H31 -> 2496110.6 | J31: Terminal Ilinka | K31: Barbarov
A32: =A31+1 -> 27 | B32: 46050 | C32: 8610498 | D32: 51308252 | E32: 56.15 | F32: 495.79 | G32: =E32*F32 -> 27838.609 | H32: 43524.16 | I32: =E32*H32 -> 2443881.6 | J32: Terminal Ilinka | K32: Barbarov
A33: =A32+1 -> 28 | B33: 46050 | C33: 8610498 | D33: 57446692 | E33: 58.65 | F33: 495.79 | G33: =E33*F33 -> 29078.084 | H33: 43524.16 | I33: =E33*H33 -> 2552692 | J33: Terminal Ilinka | K33: Barbarov
A34: =A33+1 -> 29 | B34: 46050 | C34: 8610498 | D34: 73120339 | E34: 60.4 | F34: 495.79 | G34: =E34*F34 -> 29945.716 | H34: 43524.16 | I34: =E34*H34 -> 2628859.3 | J34: Terminal Ilinka | K34: Barbarov
A35: =A34+1 -> 30 | B35: 46050 | C35: 8610498 | D35: 73137333 | E35: 58.65 | F35: 495.79 | G35: =E35*F35 -> 29078.084 | H35: 43524.16 | I35: =E35*H35 -> 2552692 | J35: Terminal Ilinka | K35: Barbarov
A36: =A35+1 -> 31 | B36: 46050 | C36: 8610498 | D36: 73166217 | E36: 59.75 | F36: 495.79 | G36: =E36*F36 -> 29623.452 | H36: 43524.16 | I36: =E36*H36 -> 2600568.6 | J36: Terminal Ilinka | K36: Barbarov
A37: =A36+1 -> 32 | B37: 46050 | C37: 8610498 | D37: 73169328 | E37: 59.7 | F37: 495.79 | G37: =E37*F37 -> 29598.663 | H37: 43524.16 | I37: =E37*H37 -> 2598392.4 | J37: Terminal Ilinka | K37: Barbarov
A38: =A37+1 -> 33 | B38: 46050 | C38: 8610498 | D38: 73225385 | E38: 60.55 | F38: 495.79 | G38: =E38*F38 -> 30020.085 | H38: 43524.16 | I38: =E38*H38 -> 2635387.9 | J38: Terminal Ilinka | K38: Barbarov
A39: =A38+1 -> 34 | B39: 46050 | C39: 8610498 | D39: 73229270 | E39: 61.1 | F39: 495.79 | G39: =E39*F39 -> 30292.769 | H39: 43524.16 | I39: =E39*H39 -> 2659326.2 | J39: Terminal Ilinka | K39: Barbarov
A40: =A39+1 -> 35 | B40: 46050 | C40: 8610498 | D40: 73232035 | E40: 59.9 | F40: 495.79 | G40: =E40*F40 -> 29697.821 | H40: 43524.16 | I40: =E40*H40 -> 2607097.2 | J40: Terminal Ilinka | K40: Barbarov
E41: =SUM(E30:E40) -> 649.7 | G41: =SUM(G30:G40) -> 322114.76 | I41: =SUM(I30:I40) -> 28277647
A42: 36 | B42: 46051 | C42: 8610559 | D42: 51340032 | E42: 62.5 | F42: 495.79 | G42: =E42*F42 -> 30986.875 | H42: 43524.16 | I42: =E42*H42 -> 2720260 | J42: Terminal Ilinka | K42: Barbarov
A43: =A42+1 -> 37 | B43: 46051 | C43: 8610559 | D43: 51513380 | E43: 59.3 | F43: 495.79 | G43: =E43*F43 -> 29400.347 | H43: 43524.16 | I43: =E43*H43 -> 2580982.7 | J43: Terminal Ilinka | K43: Barbarov
A44: =A43+1 -> 38 | B44: 46051 | C44: 8610559 | D44: 53935144 | E44: 58.65 | F44: 495.79 | G44: =E44*F44 -> 29078.084 | H44: 43524.16 | I44: =E44*H44 -> 2552692 | J44: Terminal Ilinka | K44: Barbarov
A45: =A44+1 -> 39 | B45: 46051 | C45: 8610559 | D45: 53935631 | E45: 58.5 | F45: 495.79 | G45: =E45*F45 -> 29003.715 | H45: 43524.16 | I45: =E45*H45 -> 2546163.4 | J45: Terminal Ilinka | K45: Barbarov
A46: =A45+1 -> 40 | B46: 46051 | C46: 8610559 | D46: 54696091 | E46: 62.4 | F46: 495.79 | G46: =E46*F46 -> 30937.296 | H46: 43524.16 | I46: =E46*H46 -> 2715907.6 | J46: Terminal Ilinka | K46: Barbarov
A47: =A46+1 -> 41 | B47: 46051 | C47: 8610559 | D47: 73185563 | E47: 62.1 | F47: 495.79 | G47: =E47*F47 -> 30788.559 | H47: 43524.16 | I47: =E47*H47 -> 2702850.3 | J47: Terminal Ilinka | K47: Barbarov
A48: =A47+1 -> 42 | B48: 46051 | C48: 8610559 | D48: 73964405 | E48: 61.35 | F48: 495.79 | G48: =E48*F48 -> 30416.717 | H48: 43524.16 | I48: =E48*H48 -> 2670207.2 | J48: Terminal Ilinka | K48: Barbarov
A49: =A48+1 -> 43 | B49: 46051 | C49: 8610559 | D49: 75056986 | E49: 64.25 | F49: 495.79 | G49: =E49*F49 -> 31854.507 | H49: 43524.16 | I49: =E49*H49 -> 2796427.3 | J49: Terminal Ilinka | K49: Barbarov
A50: =A49+1 -> 44 | B50: 46051 | C50: 8610559 | D50: 75295915 | E50: 64.9 | F50: 495.79 | G50: =E50*F50 -> 32176.771 | H50: 43524.16 | I50: =E50*H50 -> 2824718 | J50: Terminal Ilinka | K50: Barbarov
...

Sheet 37 - M -15000 MT Gasoline -70
A1: Contract BNK-KHM/9-4-12/140 dd 29.07.2022, between "BNK-FZCO" (UAE) and "KHUMOR" LLC (KYRGYZ REPUBLIC) | T1: AI-92-K5
A2: ADDENDUM № 37-M dd 19.03.26 (DAP TRUSOVO) 15'000 mt
F3: -70$
A4: № | B4: Date | C4: RWB No | D4: Wagons No | E4: Loaded quantity (MT) | F4: Price in January 01.03.26-31.03.26 $ | G4: Total | H4: Fix price in rub | I4: Total | J4: Consignee | K4: Destination | M4: Transport in rub | N4: Total | O4: Transport in $ (preliminary) | P4: Total | Q4: Date of arrival of wagons | R4: Date of leak | S4: Quantity | T4: Difference | U4: Remarks
A5: 1 | B5: 46106 | C5: 8612351 | D5: 50054584 | E5: 60.15 | F5: ='[4]Platt''s 2026'!S34-70 -> 903.38636 | G5: =E5*F5 -> 54338.69 | H5: 75336.02 | I5: =E5*H5 -> 4531461.6 | J5: Terminal Ilinka | K5: Trusowo | O5: 83.02 | P5: =E5*O5 -> 4993.653
A6: =A5+1 -> 2 | B6: 46106 | C6: 8612351 | D6: 50398296 | E6: 60.1 | F6: 903.39 | G6: =E6*F6 -> 54293.739 | H6: 75336.02 | I6: =E6*H6 -> 4527694.8 | J6: Terminal Ilinka | K6: Trusowo | O6: 83.02 | P6: =E6*O6 -> 4989.502
A7: =A6+1 -> 3 | B7: 46106 | C7: 8612351 | D7: 50416825 | E7: 60.05 | F7: 903.39 | G7: =E7*F7 -> 54248.569 | H7: 75336.02 | I7: =E7*H7 -> 4523928 | J7: Terminal Ilinka | K7: Trusowo | O7: 83.02 | P7: =E7*O7 -> 4985.351
A8: =A7+1 -> 4 | B8: 46106 | C8: 8612350 | D8: 51077568 | E8: 60.65 | F8: 903.39 | G8: =E8*F8 -> 54790.603 | H8: 75336.02 | I8: =E8*H8 -> 4569129.6 | J8: Terminal Ilinka | K8: Trusowo | O8: 83.02 | P8: =E8*O8 -> 5035.163
A9: =A8+1 -> 5 | B9: 46106 | C9: 8612350 | D9: 51095644 | E9: 60.65 | F9: 903.39 | G9: =E9*F9 -> 54790.603 | H9: 75336.02 | I9: =E9*H9 -> 4569129.6 | J9: Terminal Ilinka | K9: Trusowo | O9: 83.02 | P9: =E9*O9 -> 5035.163
A10: =A9+1 -> 6 | B10: 46106 | C10: 8612350 | D10: 51216737 | E10: 60.15 | F10: 903.39 | G10: =E10*F10 -> 54338.908 | H10: 75336.02 | I10: =E10*H10 -> 4531461.6 | J10: Terminal Ilinka | K10: Trusowo | O10: 83.02 | P10: =E10*O10 -> 4993.653
A11: =A10+1 -> 7 | B11: 46106 | C11: 8612350 | D11: 51419166 | E11: 60.15 | F11: 903.39 | G11: =E11*F11 -> 54338.908 | H11: 75336.02 | I11: =E11*H11 -> 4531461.6 | J11: Terminal Ilinka | K11: Trusowo | O11: 83.02 | P11: =E11*O11 -> 4993.653
A12: =A11+1 -> 8 | B12: 46106 | C12: 8612350 | D12: 51688893 | E12: 60.1 | F12: 903.39 | G12: =E12*F12 -> 54293.739 | H12: 75336.02 | I12: =E12*H12 -> 4527694.8 | J12: Terminal Ilinka | K12: Trusowo | O12: 83.02 | P12: =E12*O12 -> 4989.502
A13: =A12+1 -> 9 | B13: 46106 | C13: 8612350 | D13: 51813103 | E13: 60.3 | F13: 903.39 | G13: =E13*F13 -> 54474.417 | H13: 75336.02 | I13: =E13*H13 -> 4542762 | J13: Terminal Ilinka | K13: Trusowo | O13: 83.02 | P13: =E13*O13 -> 5006.106
A14: =A13+1 -> 10 | B14: 46106 | C14: 8612350 | D14: 54075502 | E14: 60.1 | F14: 903.39 | G14: =E14*F14 -> 54293.739 | H14: 75336.02 | I14: =E14*H14 -> 4527694.8 | J14: Terminal Ilinka | K14: Trusowo | O14: 83.02 | P14: =E14*O14 -> 4989.502
A15: =A14+1 -> 11 | B15: 46106 | C15: 8612351 | D15: 54092374 | E15: 60.05 | F15: 903.39 | G15: =E15*F15 -> 54248.569 | H15: 75336.02 | I15: =E15*H15 -> 4523928 | J15: Terminal Ilinka | K15: Trusowo | O15: 83.02 | P15: =E15*O15 -> 4985.351
A16: =A15+1 -> 12 | B16: 46106 | C16: 8612351 | D16: 54095849 | E16: 60.35 | F16: 903.39 | G16: =E16*F16 -> 54519.586 | H16: 75336.02 | I16: =E16*H16 -> 4546528.8 | J16: Terminal Ilinka | K16: Trusowo | O16: 83.02 | P16: =E16*O16 -> 5010.257
A17: =A16+1 -> 13 | B17: 46106 | C17: 8612350 | D17: 54243910 | E17: 60.55 | F17: 903.39 | G17: =E17*F17 -> 54700.264 | H17: 75336.02 | I17: =E17*H17 -> 4561596 | J17: Terminal Ilinka | K17: Trusowo | O17: 83.02 | P17: =E17*O17 -> 5026.861
... A38: =A37+1 -> 34 | B38: 46106 | C38: 8612351 | D38: 75291559 | E38: 60.95 | F38: 903.39 | G38: =E38*F38 -> 55061.621 | H38: 75336.02 | I38: =E38*H38 -> 4591730.4 | J38: Terminal Ilinka | K38: Trusowo | O38: 83.02 | P38: =E38*O38 -> 5060.069
E39: =SUM(E5:E38) -> 2056.8 | G39: =SUM(G5:G38) -> 1858092.3 | I39: =SUM(I5:I38) -> 1.5495113e+08 | P39: =SUM(P5:P38) -> 170755.54
A40: 35 | B40: 46108 | C40: 8612382 | D40: 50786052 | E40: 51.35 | F40: 903.39 | G40: =E40*F40 -> 46389.077 | H40: 75336.02 | I40: =E40*H40 -> 3868504.6 | J40: Terminal Ilinka | K40: Trusowo | O40: 83.02 | P40: =E40*O40 -> 4263.077
A41: =A40+1 -> 36 | B41: 46108 | C41: 8612382 | D41: 51247757 | E41: 60.05 | F41: 903.39 | G41: =E41*F41 -> 54248.569 | H41: 75336.02 | I41: =E41*H41 -> 4523928 | J41: Terminal Ilinka | K41: Trusowo | O41: 83.02 | P41: =E41*O41 -> 4985.351
A42: =A41+1 -> 37 | B42: 46108 | C42: 8612382 | D42: 53872081 | E42: 60.2 | F42: 903.39 | G42: =E42*F42 -> 54384.078 | H42: 75336.02 | I42: =E42*H42 -> 4535228.4 | J42: Terminal Ilinka | K42: Trusowo | O42: 83.02 | P42: =E42*O42 -> 4997.804
A43: =A42+1 -> 38 | B43: 46108 | C43: 8612382 | D43: 55306948 | E43: 60.2 | F43: 903.39 | G43: =E43*F43 -> 54384.078 | H43: 75336.02 | I43: =E43*H43 -> 4535228.4 | J43: Terminal Ilinka | K43: Trusowo | O43: 83.02 | P43: =E43*O43 -> 4997.804
A44: =A43+1 -> 39 | B44: 46108 | C44: 8612382 | D44: 57010274 | E44: 60.75 | F44: 903.39 | G44: =E44*F44 -> 54880.942 | H44: 75336.02 | I44: =E44*H44 -> 4576663.2 | J44: Terminal Ilinka | K44: Trusowo | O44: 83.02 | P44: =E44*O44 -> 5043.465
A45: =A44+1 -> 40 | B45: 46108 | C45: 8612382 | D45: 75032425 | E45: 60.8 | F45: 903.39 | G45: =E45*F45 -> 54926.112 | H45: 75336.02 | I45: =E45*H45 -> 4580430 | J45: Terminal Ilinka | K45: Trusowo | O45: 83.02 | P45: =E45*O45 -> 5047.616
E46: =SUM(E40:E45) -> 353.35 | G46: =SUM(G40:G45) -> 319212.86 | I46: =SUM(I40:I45) -> 26619983 | P46: =SUM(P40:P45) -> 29335.117
A47: 41 | B47: 46109 | C47: 8612392 | D47: 51254498 | E47: 50.7 | F47: 903.39 | G47: =E47*F47 -> 45801.873 | H47: 75336.02 | I47: =E47*H47 -> 3819536.2 | J47: Terminal Ilinka | K47: Trusowo | O47: 83.02 | P47: =E47*O47 -> 4209.114
A48: =A47+1 -> 42 | B48: 46109 | C48: 8612392 | D48: 51463206 | E48: 50.75 | F48: 903.39 | G48: =E48*F48 -> 45847.042 | H48: 75336.02 | I48: =E48*H48 -> 3823303 | J48: Terminal Ilinka | K48: Trusowo | O48: 83.02 | P48: =E48*O48 -> 4213.265
A49: =A48+1 -> 43 | B49: 46109 | C49: 8612392 | D49: 73013674 | E49: 60.4 | F49: 903.39 | G49: =E49*F49 -> 54564.756 | H49: 75336.02 | I49: =E49*H49 -> 4550295.6 | J49: Terminal Ilinka | K49: Trusowo | O49: 83.02 | P49: =E49*O49 -> 5014.408
A50: =A49+1 -> 44 | B50: 46109 | C50: 8612392 | D50: 75208835 | E50: 60.65 | F50: 903.39 | G50: =E50*F50 -> 54790.603 | H50: 75336.02 | I50: =E50*H50 -> 4569129.6 | J50: Terminal Ilinka | K50: Trusowo | O50: 83.02 | P50: =E50*O50 -> 5035.163
A51: =A50+1 -> 45 | B51: 46109 | C51: 8612392 | D51: 75283051 | E51: 60.65 | F51: 903.39 | G51: =E51*F51 -> 54790.603 | H51: 75336.02 | I51: =E51*H51 -> 4569129.6 | J51: Terminal Ilinka | K51: Trusowo | O51: 83.02 | P51: =E51*O51 -> 5035.163
A52: =A51+1 -> 46 | B52: 46109 | C52: 8612392 | D52: 75309278 | E52: 60.65 | F52: 903.39 | G52: =E52*F52 -> 54790.603 | H52: 75336.02 | I52: =E52*H52 -> 4569129.6 | J52: Terminal Ilinka | K52: Trusowo | O52: 83.02 | P52: =E52*O52 -> 5035.163
A53: =A52+1 -> 47 | B53: 46109 | C53: 8612392 | D53: 75867697 | E53: 60.6 | F53: 903.39 | G53: =E53*F53 -> 54745.434 | H53: 75336.02 | I53: =E53*H53 -> 4565362.8 | J53: Terminal Ilinka | K53: Trusowo | O53: 83.02 | P53: =E53*O53 -> 5031.012
A54: =A53+1 -> 48 | B54: 46109 | C54: 8612393 | D54: 50309194 | E54: 59.85 | F54: 903.39 | G54: =E54*F54 -> 54067.891 | H54: 75336.02 | I54: =E54*H54 -> 4508860.8 | J54: Terminal Ilinka | K54: Trusowo | O54: 83.02 | P54: =E54*O54 -> 4968.747
A55: =A54+1 -> 49 | B55: 46109 | C55: 8612390 | D55: 50362367 | E55: 52.15 | F55: 903.39 | G55: =E55*F55 -> 47111.788 | H55: 75336.02 | I55: =E55*H55 -> 3928773.4 | J55: Terminal Ilinka | K55: Trusowo | O55: 83.02 | P55: =E55*O55 -> 4329.493
A56: =A55+1 -> 50 | B56: 46109 | C56: 8612390 | D56: 50375930 | E56: 52.2 | F56: 903.39 | G56: =E56*F56 -> 47156.958 | H56: 75336.02 | I56: =E56*H56 -> 3932540.2 | J56: Terminal Ilinka | K56: Trusowo | O56: 83.02 | P56: =E56*O56 -> 4333.644
A57: =A56+1 -> 51 | B57: 46109 | C57: 8612391 | D57: 50413830 | E57: 59.85 | F57: 903.39 | G57: =E57*F57 -> 54067.891 | H57: 75336.02 | I57: =E57*H57 -> 4508860.8 | J57: Terminal Ilinka | K57: Trusowo | O57: 83.02 | P57: =E57*O57 -> 4968.747
A58: =A57+1 -> 52 | B58: 46109 | C58: 8612389 | D58: 50484666 | E58: 59.9 | F58: 903.39 | G58: =E58*F58 -> 54113.061 | H58: 75336.02 | I58: =E58*H58 -> 4512627.6 | J58: Terminal Ilinka | K58: Trusowo | O58: 83.02 | P58: =E58*O58 -> 4972.898
A59: =A58+1 -> 53 | B59: 46109 | C59: 8612391 | D59: 50485200 | E59: 59.85 | F59: 903.39 | G59: =E59*F59 -> 54067.891 | H59: 75336.02 | I59: =E59*H59 -> 4508860.8 | J59: Terminal Ilinka | K59: Trusowo | O59: 83.02 | P59: =E59*O59 -> 4968.747
... A104: =A103+1 -> 98 | B104: 46109 | C104: 8612390 | D104: 76575794 | E104: 60.65 | F104: 903.39 | G104: =E104*F104 -> 54790.603 | H104: 75336.02 | I104: =E104*H104 -> 4569129.6 | J104: Terminal Ilinka | K104: Trusowo | O104: 83.02 | P104: =E104*O104 -> 5035.163
...

Sheet 38 - M # 10000#APRIL -44
A1: Contract BNK-KHM/9-4-12/140 dd 29.07.2022, between "BNK-FZCO" (UAE) and "KHUMOR" LLC (KYRGYZ REPUBLIC) | T1: AI-92-K5
A2: ADDENDUM № 38-M dd 22.04.26 (DAP TRUSOVO)
G3: Agreement № 1 dd 22.04.2026 | T3: 10'000mt
F4: -44$
A5: № | B5: Date | C5: RWB No | D5: Wagons No | E5: Loaded quantity (MT) | F5: Price in april 01.04.26-30.04.26 $ | G5: Total | H5: Fix price in rub | I5: Total | J5: Consignee | K5: Destination | M5: Transport in rub | N5: Total | O5: Transport in $ (preliminary) | P5: Total | Q5: Date of arrival of wagons | R5: Date of leak | S5: Quantity | T5: Difference | U5: Remarks
A6: 1 | B6: 46137 | C6: 40000334 | D6: 50913581 | E6: 59.2 | F6: ='[5]Platt''s 2026'!V33-44 -> 1016.0125 | G6: =E6*F6 -> 60147.94 | H6: 76.8898 | I6: =E6*H6 -> 4551.8762 | J6: Terminal Ilinka | K6: Trusowo
A7: =A6+1 -> 2 | B7: 46137 | C7: 40000335 | D7: 51513158 | E7: 50.05 | F7: 1016.01 | G7: =E7*F7 -> 50851.3 | H7: 76.8898 | I7: =E7*H7 -> 3848.3345 | J7: Terminal Ilinka | K7: Trusowo
A8: =A7+1 -> 3 | B8: 46137 | C8: 40000335 | D8: 54702865 | E8: 59.7 | F8: 1016.01 | G8: =E8*F8 -> 60655.797 | H8: 76.8898 | I8: =E8*H8 -> 4590.3211 | J8: Terminal Ilinka | K8: Trusowo
A9: =A8+1 -> 4 | B9: 46137 | C9: 40000335 | D9: 55052153 | E9: 59.8 | F9: 1016.01 | G9: =E9*F9 -> 60757.398 | H9: 76.8898 | I9: =E9*H9 -> 4598.01 | J9: Terminal Ilinka | K9: Trusowo
A10: =A9+1 -> 5 | B10: 46137 | C10: 40000335 | D10: 57077968 | E10: 59.8 | F10: 1016.01 | G10: =E10*F10 -> 60757.398 | H10: 76.8898 | I10: =E10*H10 -> 4598.01 | J10: Terminal Ilinka | K10: Trusowo
A11: =A10+1 -> 6 | B11: 46137 | C11: 40000335 | D11: 57634198 | E11: 59.2 | F11: 1016.01 | G11: =E11*F11 -> 60147.792 | H11: 76.8898 | I11: =E11*H11 -> 4551.8762 | J11: Terminal Ilinka | K11: Trusowo
A12: =A11+1 -> 7 | B12: 46137 | C12: 40000335 | D12: 73187700 | E12: 59.8 | F12: 1016.01 | G12: =E12*F12 -> 60757.398 | H12: 76.8898 | I12: =E12*H12 -> 4598.01 | J12: Terminal Ilinka | K12: Trusowo
A13: =A12+1 -> 8 | B13: 46137 | C13: 40000335 | D13: 73197956 | E13: 59.8 | F13: 1016.01 | G13: =E13*F13 -> 60757.398 | H13: 76.8898 | I13: =E13*H13 -> 4598.01 | J13: Terminal Ilinka | K13: Trusowo
A14: =A13+1 -> 9 | B14: 46137 | C14: 40000335 | D14: 73198210 | E14: 59.85 | F14: 1016.01 | G14: =E14*F14 -> 60808.198 | H14: 76.8898 | I14: =E14*H14 -> 4601.8545 | J14: Terminal Ilinka | K14: Trusowo
A15: =A14+1 -> 10 | B15: 46137 | C15: 40000335 | D15: 74084245 | E15: 59.8 | F15: 1016.01 | G15: =E15*F15 -> 60757.398 | H15: 76.8898 | I15: =E15*H15 -> 4598.01 | J15: Terminal Ilinka | K15: Trusowo
A16: =A15+1 -> 11 | B16: 46137 | C16: 40000334 | D16: 75316208 | E16: 60.3 | F16: 1016.01 | G16: =E16*F16 -> 61265.403 | H16: 76.8898 | I16: =E16*H16 -> 4636.4549 | J16: Terminal Ilinka | K16: Trusowo
A17: =A16+1 -> 12 | B17: 46137 | C17: 40000334 | D17: 75316265 | E17: 60.25 | F17: 1016.01 | G17: =E17*F17 -> 61214.603 | H17: 76.8898 | I17: =E17*H17 -> 4632.6104 | J17: Terminal Ilinka | K17: Trusowo
A18: =A17+1 -> 13 | B18: 46137 | C18: 40000334 | D18: 75316356 | E18: 60.45 | F18: 1016.01 | G18: =E18*F18 -> 61417.805 | H18: 76.8898 | I18: =E18*H18 -> 4647.9884 | J18: Terminal Ilinka | K18: Trusowo
... A21: =A20+1 -> 16 | B21: 46137 | C21: 40000334 | D21: 75318881 | E21: 60.3 | F21: 1016.01 | G21: =E21*F21 -> 61265.403 | H21: 76.8898 | I21: =E21*H21 -> 4636.4549 | J21: Terminal Ilinka | K21: Trusowo
E22: =SUM(E6:E21) -> 949.35 | G22: =SUM(G6:G21) -> 964549.24 | I22: =SUM(I6:I21) -> 72995.332
A23: 17 | B23: 46139 | C23: 40000615 | D23: 50175595 | E23: 60.3 | F23: 1016.01 | G23: =E23*F23 -> 61265.403 | H23: 76.8898 | I23: =E23*H23 -> 4636.4549 | J23: Terminal Ilinka | K23: Trusowo
A24: =A23+1 -> 18 | B24: 46139 | C24: 40000615 | D24: 50485044 | E24: 59.3 | F24: 1016.01 | G24: =E24*F24 -> 60249.393 | H24: 76.8898 | I24: =E24*H24 -> 4559.5651 | J24: Terminal Ilinka | K24: Trusowo
A25: =A24+1 -> 19 | B25: 46139 | C25: 40000616 | D25: 51247757 | E25: 59.4 | F25: 1016.01 | G25: =E25*F25 -> 60350.994 | H25: 76.8898 | I25: =E25*H25 -> 4567.2541 | J25: Terminal Ilinka | K25: Trusowo
A26: =A25+1 -> 20 | B26: 46139 | C26: 40000616 | D26: 51404655 | E26: 59.25 | F26: 1016.01 | G26: =E26*F26 -> 60198.592 | H26: 76.8898 | I26: =E26*H26 -> 4555.7206 | J26: Terminal Ilinka | K26: Trusowo
A27: =A26+1 -> 21 | B27: 46139 | C27: 40000615 | D27: 51435451 | E27: 51 | F27: 1016.01 | G27: =E27*F27 -> 51816.51 | H27: 76.8898 | I27: =E27*H27 -> 3921.3798 | J27: Terminal Ilinka | K27: Trusowo
A28: =A27+1 -> 22 | B28: 46139 | C28: 40000615 | D28: 51543791 | E28: 59.05 | F28: 1016.01 | G28: =E28*F28 -> 59995.39 | H28: 76.8898 | I28: =E28*H28 -> 4540.3427 | J28: Terminal Ilinka | K28: Trusowo
A29: =A28+1 -> 23 | B29: 46139 | C29: 40000616 | D29: 53872081 | E29: 59.25 | F29: 1016.01 | G29: =E29*F29 -> 60198.592 | H29: 76.8898 | I29: =E29*H29 -> 4555.7206 | J29: Terminal Ilinka | K29: Trusowo
A30: =A29+1 -> 24 | B30: 46139 | C30: 40000615 | D30: 54596887 | E30: 59.3 | F30: 1016.01 | G30: =E30*F30 -> 60249.393 | H30: 76.8898 | I30: =E30*H30 -> 4559.5651 | J30: Terminal Ilinka | K30: Trusowo
A31: =A30+1 -> 25 | B31: 46139 | C31: 40000616 | D31: 57134157 | E31: 59.2 | F31: 1016.01 | G31: =E31*F31 -> 60147.792 | H31: 76.8898 | I31: =E31*H31 -> 4551.8762 | J31: Terminal Ilinka | K31: Trusowo
A32: =A31+1 -> 26 | B32: 46139 | C32: 40000616 | D32: 57173874 | E32: 59.7 | F32: 1016.01 | G32: =E32*F32 -> 60655.797 | H32: 76.8898 | I32: =E32*H32 -> 4590.3211 | J32: Terminal Ilinka | K32: Trusowo
A33: =A32+1 -> 27 | B33: 46139 | C33: 40000616 | D33: 57643892 | E33: 59.45 | F33: 1016.01 | G33: =E33*F33 -> 60401.795 | H33: 76.8898 | I33: =E33*H33 -> 4571.0986 | J33: Terminal Ilinka | K33: Trusowo
A34: =A33+1 -> 28 | B34: 46139 | C34: 40000616 | D34: 58709866 | E34: 59.75 | F34: 1016.01 | G34: =E34*F34 -> 60706.597 | H34: 76.8898 | I34: =E34*H34 -> 4594.1655 | J34: Terminal Ilinka | K34: Trusowo
A35: =A34+1 -> 29 | B35: 46139 | C35: 40000615 | D35: 73036782 | E35: 59.75 | F35: 1016.01 | G35: =E35*F35 -> 60706.597 | H35: 76.8898 | I35: =E35*H35 -> 4594.1655 | J35: Terminal Ilinka | K35: Trusowo
... A43: =A42+1 -> 37 | B43: 46139 | C43: 40000615 | D43: 75332239 | E43: 60.4 | F43: 1016.01 | G43: =E43*F43 -> 61367.004 | H43: 76.8898 | I43: =E43*H43 -> 4644.1439 | J43: Terminal Ilinka | K43: Trusowo
E44: =SUM(E23:E43) -> 1243.65 | G44: =SUM(G23:G43) -> 1263560.8 | I44: =SUM(I23:I43) -> 95624
A45: 38 | B45: 46140 | C45: 40000620 | D45: 50919323 | E45: 59.85 | F45: 1016.01 | G45: =E45*F45 -> 60808.198 | H45: 76.8898 | I45: =E45*H45 -> 4601.8545 | J45: Terminal Ilinka | K45: Trusowo
A46: =A45+1 -> 39 | B46: 46140 | C46: 40000620 | D46: 54695846 | E46: 59.9 | F46: 1016.01 | G46: =E46*F46 -> 60858.999 | H46: 76.8898 | I46: =E46*H46 -> 4605.699 | J46: Terminal Ilinka | K46: Trusowo
A47: =A46+1 -> 40 | B47: 46140 | C47: 40000620 | D47: 55948871 | E47: 59.85 | F47: 1016.01 | G47: =E47*F47 -> 60808.198 | H47: 76.8898 | I47: =E47*H47 -> 4601.8545 | J47: Terminal Ilinka | K47: Trusowo
A48: =A47+1 -> 41 | B48: 46140 | C48: 40000620 | D48: 57261729 | E48: 60 | F48: 1016.01 | G48: =E48*F48 -> 60960.6 | H48: 76.8898 | I48: =E48*H48 -> 4613.388 | J48: Terminal Ilinka | K48: Trusowo
A49: =A48+1 -> 42 | B49: 46140 | C49: 40000620 | D49: 58294174 | E49: 59.95 | F49: 1016.01 | G49: =E49*F49 -> 60909.8 | H49: 76.8898 | I49: =E49*H49 -> 4609.5435 | J49: Terminal Ilinka | K49: Trusowo
...

Sheet 39 - M # 10000 # MAY -41
A1: Contract BNK-KHM/9-4-12/140 dd 29.07.2022, between "BNK-FZCO" (UAE) and "KHUMOR" LLC (KYRGYZ REPUBLIC) | T1: AI-92-K5
A2: ADDENDUM № 39-M dd 30.04.26 (DAP TRUSOVO)
F3: -41$ | T3: 10'000mt
A4: № | B4: Date | C4: RWB No | D4: Wagons No | E4: Loaded quantity (MT) | F4: Price in may 01.05.26-31.05.26 $ | G4: Total | H4: Fix price in rub | I4: Total | J4: Consignee | K4: Destination | M4: Transport in rub | N4: Total | O4: Transport in $ (preliminary) | P4: Total | Q4: Date of arrival of wagons | R4: Date of leak | S4: Quantity | T4: Difference | U4: Remarks
A5: 1 | B5: 46149 | C5: 40001542 | D5: 50071216 | E5: 51.4 | F5: ='[6]Platt''s 2026'!Z34-41 -> 1086.1447 | G5: =E5*F5 -> 55827.839 | H5: 82601.11 | I5: =E5*H5 -> 4245697.1 | J5: Terminal Ilinka | K5: Trusowo
A6: =A5+1 -> 2 | B6: 46149 | C6: 40001542 | D6: 50391234 | E6: 58.95 | F6: 1086.14 | G6: =E6*F6 -> 64027.953 | H6: 82601.11 | I6: =E6*H6 -> 4869335.4 | J6: Terminal Ilinka | K6: Trusowo
A7: =A6+1 -> 3 | B7: 46149 | C7: 40001542 | D7: 50768233 | E7: 50.15 | F7: 1086.14 | G7: =E7*F7 -> 54469.921 | H7: 82601.11 | I7: =E7*H7 -> 4142445.7 | J7: Terminal Ilinka | K7: Trusowo
A8: =A7+1 -> 4 | B8: 46149 | C8: 40001542 | D8: 50774322 | E8: 50.55 | F8: 1086.14 | G8: =E8*F8 -> 54904.377 | H8: 82601.11 | I8: =E8*H8 -> 4175486.1 | J8: Terminal Ilinka | K8: Trusowo
A9: =A8+1 -> 5 | B9: 46149 | C9: 40001542 | D9: 50778943 | E9: 50.45 | F9: 1086.14 | G9: =E9*F9 -> 54795.763 | H9: 82601.11 | I9: =E9*H9 -> 4167226 | J9: Terminal Ilinka | K9: Trusowo
A10: =A9+1 -> 6 | B10: 46149 | C10: 40001542 | D10: 50786771 | E10: 50.15 | F10: 1086.14 | G10: =E10*F10 -> 54469.921 | H10: 82601.11 | I10: =E10*H10 -> 4142445.7 | J10: Terminal Ilinka | K10: Trusowo
A11: =A10+1 -> 7 | B11: 46149 | C11: 40001542 | D11: 50960707 | E11: 59.1 | F11: 1086.14 | G11: =E11*F11 -> 64190.874 | H11: 82601.11 | I11: =E11*H11 -> 4881725.6 | J11: Terminal Ilinka | K11: Trusowo
A12: =A11+1 -> 8 | B12: 46149 | C12: 40001542 | D12: 51217610 | E12: 50.8 | F12: 1086.14 | G12: =E12*F12 -> 55175.912 | H12: 82601.11 | I12: =E12*H12 -> 4196136.4 | J12: Terminal Ilinka | K12: Trusowo
A13: =A12+1 -> 9 | B13: 46149 | C13: 40001542 | D13: 51231413 | E13: 50.75 | F13: 1086.14 | G13: =E13*F13 -> 55121.605 | H13: 82601.11 | I13: =E13*H13 -> 4192006.3 | J13: Terminal Ilinka | K13: Trusowo
A14: =A13+1 -> 10 | B14: 46149 | C14: 40001542 | D14: 51289874 | E14: 50.2 | F14: 1086.14 | G14: =E14*F14 -> 54524.228 | H14: 82601.11 | I14: =E14*H14 -> 4146575.7 | J14: Terminal Ilinka | K14: Trusowo
A15: =A14+1 -> 11 | B15: 46149 | C15: 40001542 | D15: 51487775 | E15: 58.85 | F15: 1086.14 | G15: =E15*F15 -> 63919.339 | H15: 82601.11 | I15: =E15*H15 -> 4861075.3 | J15: Terminal Ilinka | K15: Trusowo
A16: =A15+1 -> 12 | B16: 46149 | C16: 40001542 | D16: 51630762 | E16: 49.85 | F16: 1086.14 | G16: =E16*F16 -> 54144.079 | H16: 82601.11 | I16: =E16*H16 -> 4117665.3 | J16: Terminal Ilinka | K16: Trusowo
A17: =A16+1 -> 13 | B17: 46149 | C17: 40001542 | D17: 51812808 | E17: 59.05 | F17: 1086.14 | G17: =E17*F17 -> 64136.567 | H17: 82601.11 | I17: =E17*H17 -> 4877595.5 | J17: Terminal Ilinka | K17: Trusowo
... A24: =A23+1 -> 20 | B24: 46149 | C24: 40001542 | D24: 73131427 | E24: 59.35 | F24: 1086.14 | G24: =E24*F24 -> 64462.409 | H24: 82601.11 | I24: =E24*H24 -> 4902375.9 | J24: Terminal Ilinka | K24: Trusowo
E25: =SUM(E5:E24) -> 1094.45 | G25: =SUM(G5:G24) -> 1188726.2 | I25: =SUM(I5:I24) -> 90402785
A26: 21 | B26: 46150 | C26: 40001614 | D26: 73765687 | E26: 59.35 | F26: 1086.14 | G26: =E26*F26 -> 64462.409 | H26: 82601.11 | I26: =E26*H26 -> 4902375.9 | J26: Terminal Ilinka | K26: Trusowo
A27: =A26+1 -> 22 | B27: 46150 | C27: 40001614 | D27: 50411693 | E27: 59.4 | F27: 1086.14 | G27: =E27*F27 -> 64516.716 | H27: 82601.11 | I27: =E27*H27 -> 4906505.9 | J27: Terminal Ilinka | K27: Trusowo
A28: =A27+1 -> 23 | B28: 46150 | C28: 40001614 | D28: 75852699 | E28: 59.95 | F28: 1086.14 | G28: =E28*F28 -> 65114.093 | H28: 82601.11 | I28: =E28*H28 -> 4951936.5 | J28: Terminal Ilinka | K28: Trusowo
A29: =A28+1 -> 24 | B29: 46150 | C29: 40001614 | D29: 75008144 | E29: 59.25 | F29: 1086.14 | G29: =E29*F29 -> 64353.795 | H29: 82601.11 | I29: =E29*H29 -> 4894115.8 | J29: Terminal Ilinka | K29: Trusowo
A30: =A29+1 -> 25 | B30: 46150 | C30: 40001614 | D30: 75207852 | E30: 60.1 | F30: 1086.14 | G30: =E30*F30 -> 65277.014 | H30: 82601.11 | I30: =E30*H30 -> 4964326.7 | J30: Terminal Ilinka | K30: Trusowo
A31: =A30+1 -> 26 | B31: 46150 | C31: 40001614 | D31: 76307594 | E31: 59.9 | F31: 1086.14 | G31: =E31*F31 -> 65059.786 | H31: 82601.11 | I31: =E31*H31 -> 4947806.5 | J31: Terminal Ilinka | K31: Trusowo
A32: =A31+1 -> 27 | B32: 46150 | C32: 40001614 | D32: 50438233 | E32: 59.45 | F32: 1086.14 | G32: =E32*F32 -> 64571.023 | H32: 82601.11 | I32: =E32*H32 -> 4910636 | J32: Terminal Ilinka | K32: Trusowo
A33: =A32+1 -> 28 | B33: 46150 | C33: 40001614 | D33: 51551216 | E33: 49.8 | F33: 1086.14 | G33: =E33*F33 -> 54089.772 | H33: 82601.11 | I33: =E33*H33 -> 4113535.3 | J33: Terminal Ilinka | K33: Trusowo
A34: =A33+1 -> 29 | B34: 46150 | C34: 40001614 | D34: 57201899 | E34: 59.35 | F34: 1086.14 | G34: =E34*F34 -> 64462.409 | H34: 82601.11 | I34: =E34*H34 -> 4902375.9 | J34: Terminal Ilinka | K34: Trusowo
A35: =A34+1 -> 30 | B35: 46150 | C35: 40001614 | D35: 57028649 | E35: 58.85 | F35: 1086.14 | G35: =E35*F35 -> 63919.339 | H35: 82601.11 | I35: =E35*H35 -> 4861075.3 | J35: Terminal Ilinka | K35: Trusowo
A36: =A35+1 -> 31 | B36: 46150 | C36: 40001614 | D36: 51228310 | E36: 59 | F36: 1086.14 | G36: =E36*F36 -> 64082.26 | H36: 82601.11 | I36: =E36*H36 -> 4873465.5 | J36: Terminal Ilinka | K36: Trusowo
A37: =A36+1 -> 32 | B37: 46150 | C37: 40001614 | D37: 55551824 | E37: 59.45 | F37: 1086.14 | G37: =E37*F37 -> 64571.023 | H37: 82601.11 | I37: =E37*H37 -> 4910636 | J37: Terminal Ilinka | K37: Trusowo
A38: =A37+1 -> 33 | B38: 46150 | C38: 40001614 | D38: 75113159 | E38: 59.35 | F38: 1086.14 | G38: =E38*F38 -> 64462.409 | H38: 82601.11 | I38: =E38*H38 -> 4902375.9 | J38: Terminal Ilinka | K38: Trusowo
E39: =SUM(E26:E38) -> 763.2 | G39: =SUM(G26:G38) -> 828942.05 | I39: =SUM(I26:I38) -> 63041167
A40: 34 | B40: 09 05 26 | C40: 40001709 | D40: 54095757 | E40: 58.8 | F40: 1086.14 | G40: =E40*F40 -> 63865.032 | H40: 82601.11 | I40: =E40*H40 -> 4856945.3 | J40: Terminal Ilinka | K40: Trusowo
A41: =A40+1 -> 35 | B41: 09 05 26 | C41: 40001709 | D41: 57431595 | E41: 58.8 | F41: 1086.14 | G41: =E41*F41 -> 63865.032 | H41: 82601.11 | I41: =E41*H41 -> 4856945.3 | J41: Terminal Ilinka | K41: Trusowo
A42: =A41+1 -> 36 | B42: 09 05 26 | C42: 40001709 | D42: 51622850 | E42: 58.55 | F42: 1086.14 | G42: =E42*F42 -> 63593.497 | H42: 82601.11 | I42: =E42*H42 -> 4836295 | J42: Terminal Ilinka | K42: Trusowo
A43: =A42+1 -> 37 | B43: 09 05 26 | C43: 40001709 | D43: 51622801 | E43: 58.6 | F43: 1086.14 | G43: =E43*F43 -> 63647.804 | H43: 82601.11 | I43: =E43*H43 -> 4840425 | J43: Terminal Ilinka | K43: Trusowo
